Workbook

Sheet Foglio3
A1: sigla | B1: stato_it | C1: stato_en
A2: AFG | B2: Afghanistan | C2: =TRIM(VLOOKUP(A2,Foglio2!$A$2:$B$287,2,0)) -> Afghanistan
A3: ALB | B3: Albania | C3: =TRIM(VLOOKUP(A3,Foglio2!$A$2:$B$287,2,0)) -> Albania
A4: ALG | B4: Algeria | C4: =TRIM(VLOOKUP(A4,Foglio2!$A$2:$B$287,2,0)) -> Algeria
A5: AND | B5: Andorra | C5: =TRIM(VLOOKUP(A5,Foglio2!$A$2:$B$287,2,0)) -> Andorra
A6: ANG | B6: Angola | C6: =TRIM(VLOOKUP(A6,Foglio2!$A$2:$B$287,2,0)) -> Angola
A7: ANT | B7: Antigua e Barbuda | C7: =TRIM(VLOOKUP(A7,Foglio2!$A$2:$B$287,2,0)) -> Antigua and Barbuda
A8: ARG | B8: Argentina | C8: =TRIM(VLOOKUP(A8,Foglio2!$A$2:$B$287,2,0)) -> Argentina
A9: ARM | B9: Armenia | C9: =TRIM(VLOOKUP(A9,Foglio2!$A$2:$B$287,2,0)) -> Armenia
A10: ARU | B10: Aruba | C10: =TRIM(VLOOKUP(A10,Foglio2!$A$2:$B$287,2,0)) -> Aruba
A11: ASA | B11: Samoa Americane | C11: =TRIM(VLOOKUP(A11,Foglio2!$A$2:$B$287,2,0)) -> American Samoa
A12: AUS | B12: Australia | C12: =TRIM(VLOOKUP(A12,Foglio2!$A$2:$B$287,2,0)) -> Australia
A13: AUT | B13: Austria | C13: =TRIM(VLOOKUP(A13,Foglio2!$A$2:$B$287,2,0)) -> Austria
... A190: TPE | B190: Taipei cinese | C190: =TRIM(VLOOKUP(A190,Foglio2!$A$2:$B$287,2,0)) -> Republic of China[7][8][9][10]
A191: Repubblica di Cina[11] | B191: 1956 | C191: =TRIM(VLOOKUP(A191,Foglio2!$A$2:$B$287,2,0)) -> #N/A
A192: TTO | B192: Trinidad e Tobago | C192: =TRIM(VLOOKUP(A192,Foglio2!$A$2:$B$287,2,0)) -> Trinidad and Tobago
A193: TUN | B193: Tunisia | C193: =TRIM(VLOOKUP(A193,Foglio2!$A$2:$B$287,2,0)) -> Tunisia
A194: TUR | B194: Turchia | C194: =TRIM(VLOOKUP(A194,Foglio2!$A$2:$B$287,2,0)) -> Turkey
A195: TUV | B195: Tuvalu | C195: =TRIM(VLOOKUP(A195,Foglio2!$A$2:$B$287,2,0)) -> Tuvalu
A196: UAE | B196: Emirati Arabi Uniti | C196: =TRIM(VLOOKUP(A196,Foglio2!$A$2:$B$287,2,0)) -> United Arab Emirates
A197: UGA | B197: Uganda | C197: =TRIM(VLOOKUP(A197,Foglio2!$A$2:$B$287,2,0)) -> Uganda
A198: UKR | B198: Ucraina | C198: =TRIM(VLOOKUP(A198,Foglio2!$A$2:$B$287,2,0)) -> Ukraine
A199: URU | B199: Uruguay | C199: =TRIM(VLOOKUP(A199,Foglio2!$A$2:$B$287,2,0)) -> Uruguay
A200: USA | B200: Stati Uniti d'America | C200: =TRIM(VLOOKUP(A200,Foglio2!$A$2:$B$287,2,0)) -> United States
A201: UZB | B201: Uzbekistan | C201: =TRIM(VLOOKUP(A201,Foglio2!$A$2:$B$287,2,0)) -> Uzbekistan
A202: VAN | B202: Vanuatu | C202: =TRIM(VLOOKUP(A202,Foglio2!$A$2:$B$287,2,0)) -> Vanuatu
A203: VEN | B203: Venezuela | C203: =TRIM(VLOOKUP(A203,Foglio2!$A$2:$B$287,2,0)) -> Venezuela
... A208: ZIM | B208: Zimbabwe | C208: =TRIM(VLOOKUP(A208,Foglio2!$A$2:$B$287,2,0)) -> Zimbabwe

Sheet Foglio2
A2: AFG | B2: Afghanistan | D2: [1]
A3: ALB | B3: Albania | D3: [2]
A4: ALG | B4: Algeria
A5: AGR (1964)AGL (1968 S) from Spanish Argelia
A6: [3]
A7: AND | B7: Andorra | D7: [4]
A8: ANG | B8: Angola | C8: ANO (As referenced in IAAF World Championships Beijing 2015 Statistics Handbook)[1] | D8: [5]
A9: ANT | B9: Antigua and Barbuda | D9: [6]
A10: ARG | B10: Argentina | D10: [7]
A11: ARM | B11: Armenia | D11: [8]
A12: ARU | B12: Aruba | D12: [9]
A13: ASA | B13: American Samoa | C13: AMS[1] | D13: [10]
A14: AUS | B14: Australia | D14: [11]
A15: AUT | B15: Austria | C15: current code from French Autriche | D15: [12]
A16: AZE | B16: Azerbaijan | D16: [13]
A17: BAH | B17: Bahamas | D17: [14]
A18: BAN | B18: Bangladesh | D18: [15]
A19: BAR | B19: Barbados | C19: BAD (1964)[a] | D19: [16]
A20: BDI | B20: Burundi | D20: [17]
A21: BEL | B21: Belgium | D21: [18]
A22: BEN | B22: Benin
A23: DAY (1964)DAH (1968–1976) as Dahomey
A24: [19]
A25: BER | B25: Bermuda | D25: [20]
A26: BHU | B26: Bhutan | D26: [21]
A27: BIH | B27: Bosnia and Herzegovina | C27: BSH (1992 S), BOS[1] current code from Bosnian Bosna i Hercegovina | D27: [22]
A28: BIZ | B28: Belize | C28: HBR (1968–1972) from French Honduras britannique as British Honduras; also BHO[1] | D28: [23]
A29: BLR | B29: Belarus | D29: [24]
A30: BOL | B30: Bolivia | D30: [25]
A31: BOT | B31: Botswana | D31: [26]
A32: BRA | B32: Brazil | D32: [27]
A33: BRN | B33: Bahrain | C33: BHR[1] | D33: [28]
A34: BRU | B34: Brunei | D34: [29]
A35: BUL | B35: Bulgaria | D35: [30]
A36: BUR | B36: Burkina Faso | C36: VOL (1972–1984) as Upper Volta; also BKF[1] | D36: [31]
A37: CAF | B37: Central African Republic | C37: AFC (1968) | D37: [32]
A38: CAM | B38: Cambodia
A39: CAB (1964)KHM (1972) as Khmer Republic
A40: [33]
A41: CAN | B41: Canada | D41: [34]
...
